
[2025-03-25 11:14:35.027307] Traceback (most recent call last):
  File "D:\DKA\dev\VSC_Projects\pythonBotProject\handlers\admin.py", line 212, in process_rejection
    submission[1],
    ~~~~~~~~~~^^^
KeyError: 1


[2025-03-25 11:18:34.475731] Traceback (most recent call last):
  File "D:\DKA\dev\VSC_Projects\pythonBotProject\handlers\admin.py", line 214, in process_rejection
    reply_markup=Menu.main_menu()
                 ^^^^^^^^^^^^^^
AttributeError: type object 'Menu' has no attribute 'main_menu'. Did you mean: 'adm_menu'?


[2025-03-25 12:21:02.997137] Traceback (most recent call last):
  File "D:\DKA\dev\VSC_Projects\pythonBotProject\handlers\admin.py", line 211, in show_stats
    bot.send_message(
    ~~~~~~~~~~~~~~~~^
        call.message.chat.id,
        ^^^^^^^^^^^^^^^^^^^^^
    ...<4 lines>...
        reply_markup=Menu.back_adm_contest_menu(),
        ^^^^^^^^^^^^^^^^^^^^^^^^^^^^^^^^^^^^^^^^^^
    )
    ^
  File "c:\Users\Lenovo\AppData\Local\Programs\Python\Python313\Lib\site-packages\telebot\__init__.py", line 1800, in send_message
    apihelper.send_message(
    ~~~~~~~~~~~~~~~~~~~~~~^
        self.token, chat_id, text,
        ^^^^^^^^^^^^^^^^^^^^^^^^^^
    ...<2 lines>...
        reply_parameters=reply_parameters, link_preview_options=link_preview_options, business_connection_id=business_connection_id,
        ^^^^^^^^^^^^^^^^^^^^^^^^^^^^^^^^^^^^^^^^^^^^^^^^^^^^^^^^^^^^^^^^^^^^^^^^^^^^^^^^^^^^^^^^^^^^^^^^^^^^^^^^^^^^^^^^^^^^^^^^^^^^
        message_effect_id=message_effect_id, allow_paid_broadcast=allow_paid_broadcast))
        ^^^^^^^^^^^^^^^^^^^^^^^^^^^^^^^^^^^^^^^^^^^^^^^^^^^^^^^^^^^^^^^^^^^^^^^^^^^^^^^
  File "c:\Users\Lenovo\AppData\Local\Programs\Python\Python313\Lib\site-packages\telebot\apihelper.py", line 275, in send_message
    return _make_request(token, method_url, params=payload, method='post')
  File "c:\Users\Lenovo\AppData\Local\Programs\Python\Python313\Lib\site-packages\telebot\apihelper.py", line 168, in _make_request
    json_result = _check_result(method_name, result)
  File "c:\Users\Lenovo\AppData\Local\Programs\Python\Python313\Lib\site-packages\telebot\apihelper.py", line 195, in _check_result
    raise ApiTelegramException(method_name, result, result_json)
telebot.apihelper.ApiTelegramException: A request to the Telegram API was unsuccessful. Error code: 400. Description: Bad Request: unsupported parse_mode


[2025-03-25 17:20:16.789542] Traceback (most recent call last):
  File "D:\DKA\dev\VSC_Projects\pythonBotProject\handlers\admin.py", line 411, in show_submission_details
    bot.edit_message_text(
    ~~~~~~~~~~~~~~~~~~~~~^
        call.message.chat.id,
        ^^^^^^^^^^^^^^^^^^^^^
        f"Действия для работы #{submission_id}:",
        ^^^^^^^^^^^^^^^^^^^^^^^^^^^^^^^^^^^^^^^^^
        reply_markup=markup,
        ^^^^^^^^^^^^^^^^^^^^
    )
    ^
  File "c:\Users\Lenovo\AppData\Local\Programs\Python\Python313\Lib\site-packages\telebot\__init__.py", line 4974, in edit_message_text
    result = apihelper.edit_message_text(
        self.token, text, chat_id=chat_id, message_id=message_id, inline_message_id=inline_message_id,
        parse_mode=parse_mode, entities=entities, reply_markup=reply_markup, link_preview_options=link_preview_options,
        business_connection_id=business_connection_id, timeout=timeout)
  File "c:\Users\Lenovo\AppData\Local\Programs\Python\Python313\Lib\site-packages\telebot\apihelper.py", line 1507, in edit_message_text
    return _make_request(token, method_url, params=payload, method='post')
  File "c:\Users\Lenovo\AppData\Local\Programs\Python\Python313\Lib\site-packages\telebot\apihelper.py", line 168, in _make_request
    json_result = _check_result(method_name, result)
  File "c:\Users\Lenovo\AppData\Local\Programs\Python\Python313\Lib\site-packages\telebot\apihelper.py", line 195, in _check_result
    raise ApiTelegramException(method_name, result, result_json)
telebot.apihelper.ApiTelegramException: A request to the Telegram API was unsuccessful. Error code: 400. Description: Bad Request: chat not found

